Workbook

Sheet Acumulados_Jugadores 2026
A1: ESTADISTICAS ACUMULADAS POR JUGADOR 2026
A2: Jugador | B2: Partidos Jugados | C2: Goles | D2: Promedio de GOL | E2: Asistencias | F2: Total G + A | G2: Promedio G+A Por partido | H2: Victorias | I2: Empates | J2: Derrotas | K2: Rendimiento | L2: MVPs | M2: Promedio Malla Arquero | N2: Total Goles Acumulados | O2: Autogoles
A3: Luis Maldonado | B3: =COUNTIF('Base_Partidos 2026'!C:C,A3) -> 15 | C3: =SUMIF('Base_Partidos 2026'!C:C,A3,'Base_Partidos 2026'!E:E) -> 23 | D3: =C3/B3 -> 1.5333333 | E3: =SUMIF('Base_Partidos 2026'!C:C,A3,'Base_Partidos 2026'!F:F) -> 9 | F3: =C3+E3 -> 32 | G3: =F3/B3 -> 2.1333333 | H3: =COUNTIFS('Base_Partidos 2026'!C:C,A3,'Base_Partidos 2026'!G:G,"G") -> 7 | I3: =COUNTIFS('Base_Partidos 2026'!C:C,A3,'Base_Partidos 2026'!G:G,"E") -> 2 | J3: =COUNTIFS('Base_Partidos 2026'!C:C,A3,'Base_Partidos 2026'!G:G,"P") -> 6 | K3: =((H3*3+I3*1)/(H3+I3+J3)/3) -> 0.51111111 | L3: =COUNTIFS('Base_Partidos 2026'!C:C,A3,'Base_Partidos 2026'!H:H,"SI") -> 8
A4: Arley | B4: =COUNTIF('Base_Partidos 2026'!C:C,A4) -> 27 | C4: =SUMIF('Base_Partidos 2026'!C:C,A4,'Base_Partidos 2026'!E:E) -> 19 | D4: =C4/B4 -> 0.7037037 | E4: =SUMIF('Base_Partidos 2026'!C:C,A4,'Base_Partidos 2026'!F:F) -> 8 | F4: =C4+E4 -> 27 | G4: =F4/B4 -> 1 | H4: =COUNTIFS('Base_Partidos 2026'!C:C,A4,'Base_Partidos 2026'!G:G,"G") -> 16 | I4: =COUNTIFS('Base_Partidos 2026'!C:C,A4,'Base_Partidos 2026'!G:G,"E") -> 4 | J4: =COUNTIFS('Base_Partidos 2026'!C:C,A4,'Base_Partidos 2026'!G:G,"P") -> 7 | K4: =((H4*3+I4*1)/(H4+I4+J4)/3) -> 0.64197531 | L4: =COUNTIFS('Base_Partidos 2026'!C:C,A4,'Base_Partidos 2026'!H:H,"SI") -> 2
A5: Japs | B5: =COUNTIF('Base_Partidos 2026'!C:C,A5) -> 22 | C5: =SUMIF('Base_Partidos 2026'!C:C,A5,'Base_Partidos 2026'!E:E) -> 19 | D5: =C5/B5 -> 0.86363636 | E5: =SUMIF('Base_Partidos 2026'!C:C,A5,'Base_Partidos 2026'!F:F) -> 22 | F5: =C5+E5 -> 41 | G5: =F5/B5 -> 1.8636364 | H5: =COUNTIFS('Base_Partidos 2026'!C:C,A5,'Base_Partidos 2026'!G:G,"G") -> 13 | I5: =COUNTIFS('Base_Partidos 2026'!C:C,A5,'Base_Partidos 2026'!G:G,"E") -> 2 | J5: =COUNTIFS('Base_Partidos 2026'!C:C,A5,'Base_Partidos 2026'!G:G,"P") -> 7 | K5: =((H5*3+I5*1)/(H5+I5+J5)/3) -> 0.62121212 | L5: =COUNTIFS('Base_Partidos 2026'!C:C,A5,'Base_Partidos 2026'!H:H,"SI") -> 1
A6: Boada | B6: =COUNTIF('Base_Partidos 2026'!C:C,A6) -> 11 | C6: =SUMIF('Base_Partidos 2026'!C:C,A6,'Base_Partidos 2026'!E:E) -> 15 | D6: =C6/B6 -> 1.3636364 | E6: =SUMIF('Base_Partidos 2026'!C:C,A6,'Base_Partidos 2026'!F:F) -> 6 | F6: =C6+E6 -> 21 | G6: =F6/B6 -> 1.9090909 | H6: =COUNTIFS('Base_Partidos 2026'!C:C,A6,'Base_Partidos 2026'!G:G,"G") -> 3 | I6: =COUNTIFS('Base_Partidos 2026'!C:C,A6,'Base_Partidos 2026'!G:G,"E") -> 2 | J6: =COUNTIFS('Base_Partidos 2026'!C:C,A6,'Base_Partidos 2026'!G:G,"P") -> 6 | K6: =((H6*3+I6*1)/(H6+I6+J6)/3) -> 0.33333333 | L6: =COUNTIFS('Base_Partidos 2026'!C:C,A6,'Base_Partidos 2026'!H:H,"SI") -> 2
A7: Felipe Sasa | B7: =COUNTIF('Base_Partidos 2026'!C:C,A7) -> 14 | C7: =SUMIF('Base_Partidos 2026'!C:C,A7,'Base_Partidos 2026'!E:E) -> 14 | D7: =C7/B7 -> 1 | E7: =SUMIF('Base_Partidos 2026'!C:C,A7,'Base_Partidos 2026'!F:F) -> 7 | F7: =C7+E7 -> 21 | G7: =F7/B7 -> 1.5 | H7: =COUNTIFS('Base_Partidos 2026'!C:C,A7,'Base_Partidos 2026'!G:G,"G") -> 6 | I7: =COUNTIFS('Base_Partidos 2026'!C:C,A7,'Base_Partidos 2026'!G:G,"E") -> 2 | J7: =COUNTIFS('Base_Partidos 2026'!C:C,A7,'Base_Partidos 2026'!G:G,"P") -> 6 | K7: =((H7*3+I7*1)/(H7+I7+J7)/3) -> 0.47619048 | L7: =COUNTIFS('Base_Partidos 2026'!C:C,A7,'Base_Partidos 2026'!H:H,"SI") -> 1
A8: Abreo | B8: =COUNTIF('Base_Partidos 2026'!C:C,A8) -> 12 | C8: =SUMIF('Base_Partidos 2026'!C:C,A8,'Base_Partidos 2026'!E:E) -> 12 | D8: =C8/B8 -> 1 | E8: =SUMIF('Base_Partidos 2026'!C:C,A8,'Base_Partidos 2026'!F:F) -> 6 | F8: =C8+E8 -> 18 | G8: =F8/B8 -> 1.5 | H8: =COUNTIFS('Base_Partidos 2026'!C:C,A8,'Base_Partidos 2026'!G:G,"G") -> 6 | I8: =COUNTIFS('Base_Partidos 2026'!C:C,A8,'Base_Partidos 2026'!G:G,"E") -> 2 | J8: =COUNTIFS('Base_Partidos 2026'!C:C,A8,'Base_Partidos 2026'!G:G,"P") -> 4 | K8: =((H8*3+I8*1)/(H8+I8+J8)/3) -> 0.55555556 | L8: =COUNTIFS('Base_Partidos 2026'!C:C,A8,'Base_Partidos 2026'!H:H,"SI") -> 3
A9: Kevin Arce | B9: =COUNTIF('Base_Partidos 2026'!C:C,A9) -> 17 | C9: =SUMIF('Base_Partidos 2026'!C:C,A9,'Base_Partidos 2026'!E:E) -> 8 | D9: =C9/B9 -> 0.47058824 | E9: =SUMIF('Base_Partidos 2026'!C:C,A9,'Base_Partidos 2026'!F:F) -> 6 | F9: =C9+E9 -> 14 | G9: =F9/B9 -> 0.82352941 | H9: =COUNTIFS('Base_Partidos 2026'!C:C,A9,'Base_Partidos 2026'!G:G,"G") -> 6 | I9: =COUNTIFS('Base_Partidos 2026'!C:C,A9,'Base_Partidos 2026'!G:G,"E") -> 3 | J9: =COUNTIFS('Base_Partidos 2026'!C:C,A9,'Base_Partidos 2026'!G:G,"P") -> 8 | K9: =((H9*3+I9*1)/(H9+I9+J9)/3) -> 0.41176471 | L9: =COUNTIFS('Base_Partidos 2026'!C:C,A9,'Base_Partidos 2026'!H:H,"SI") -> 2
A10: WIL | B10: =COUNTIF('Base_Partidos 2026'!C:C,A10) -> 22 | C10: =SUMIF('Base_Partidos 2026'!C:C,A10,'Base_Partidos 2026'!E:E) -> 6 | D10: =C10/B10 -> 0.27272727 | E10: =SUMIF('Base_Partidos 2026'!C:C,A10,'Base_Partidos 2026'!F:F) -> 9 | F10: =C10+E10 -> 15 | G10: =F10/B10 -> 0.68181818 | H10: =COUNTIFS('Base_Partidos 2026'!C:C,A10,'Base_Partidos 2026'!G:G,"G") -> 5 | I10: =COUNTIFS('Base_Partidos 2026'!C:C,A10,'Base_Partidos 2026'!G:G,"E") -> 4 | J10: =COUNTIFS('Base_Partidos 2026'!C:C,A10,'Base_Partidos 2026'!G:G,"P") -> 13 | K10: =((H10*3+I10*1)/(H10+I10+J10)/3) -> 0.28787879 | L10: =COUNTIFS('Base_Partidos 2026'!C:C,A10,'Base_Partidos 2026'!H:H,"SI") -> 1
A11: Yamith | B11: =COUNTIF('Base_Partidos 2026'!C:C,A11) -> 19 | C11: =SUMIF('Base_Partidos 2026'!C:C,A11,'Base_Partidos 2026'!E:E) -> 6 | D11: =C11/B11 -> 0.31578947 | E11: =SUMIF('Base_Partidos 2026'!C:C,A11,'Base_Partidos 2026'!F:F) -> 4 | F11: =C11+E11 -> 10 | G11: =F11/B11 -> 0.52631579 | H11: =COUNTIFS('Base_Partidos 2026'!C:C,A11,'Base_Partidos 2026'!G:G,"G") -> 9 | I11: =COUNTIFS('Base_Partidos 2026'!C:C,A11,'Base_Partidos 2026'!G:G,"E") -> 2 | J11: =COUNTIFS('Base_Partidos 2026'!C:C,A11,'Base_Partidos 2026'!G:G,"P") -> 8 | K11: =((H11*3+I11*1)/(H11+I11+J11)/3) -> 0.50877193 | L11: =COUNTIFS('Base_Partidos 2026'!C:C,A11,'Base_Partidos 2026'!H:H,"SI") -> 2
A12: Silvia | B12: =COUNTIF('Base_Partidos 2026'!C:C,A12) -> 23 | C12: =SUMIF('Base_Partidos 2026'!C:C,A12,'Base_Partidos 2026'!E:E) -> 5 | D12: =C12/B12 -> 0.2173913 | E12: =SUMIF('Base_Partidos 2026'!C:C,A12,'Base_Partidos 2026'!F:F) -> 12 | F12: =C12+E12 -> 17 | G12: =F12/B12 -> 0.73913043 | H12: =COUNTIFS('Base_Partidos 2026'!C:C,A12,'Base_Partidos 2026'!G:G,"G") -> 8 | I12: =COUNTIFS('Base_Partidos 2026'!C:C,A12,'Base_Partidos 2026'!G:G,"E") -> 4 | J12: =COUNTIFS('Base_Partidos 2026'!C:C,A12,'Base_Partidos 2026'!G:G,"P") -> 11 | K12: =((H12*3+I12*1)/(H12+I12+J12)/3) -> 0.4057971 | L12: =COUNTIFS('Base_Partidos 2026'!C:C,A12,'Base_Partidos 2026'!H:H,"SI") -> 5
A13: Sergio Suarez | B13: =COUNTIF('Base_Partidos 2026'!C:C,A13) -> 25 | C13: =SUMIF('Base_Partidos 2026'!C:C,A13,'Base_Partidos 2026'!E:E) -> 5 | D13: =C13/B13 -> 0.2 | E13: =SUMIF('Base_Partidos 2026'!C:C,A13,'Base_Partidos 2026'!F:F) -> 5 | F13: =C13+E13 -> 10 | G13: =F13/B13 -> 0.4 | H13: =COUNTIFS('Base_Partidos 2026'!C:C,A13,'Base_Partidos 2026'!G:G,"G") -> 12 | I13: =COUNTIFS('Base_Partidos 2026'!C:C,A13,'Base_Partidos 2026'!G:G,"E") -> 4 | J13: =COUNTIFS('Base_Partidos 2026'!C:C,A13,'Base_Partidos 2026'!G:G,"P") -> 9 | K13: =((H13*3+I13*1)/(H13+I13+J13)/3) -> 0.53333333 | L13: =COUNTIFS('Base_Partidos 2026'!C:C,A13,'Base_Partidos 2026'!H:H,"SI") -> 2
A14: Jose | B14: =COUNTIF('Base_Partidos 2026'!C:C,A14) -> 15 | C14: =SUMIF('Base_Partidos 2026'!C:C,A14,'Base_Partidos 2026'!E:E) -> 5 | D14: =C14/B14 -> 0.33333333 | E14: =SUMIF('Base_Partidos 2026'!C:C,A14,'Base_Partidos 2026'!F:F) -> 2 | F14: =C14+E14 -> 7 | G14: =F14/B14 -> 0.46666667 | H14: =COUNTIFS('Base_Partidos 2026'!C:C,A14,'Base_Partidos 2026'!G:G,"G") -> 9 | I14: =COUNTIFS('Base_Partidos 2026'!C:C,A14,'Base_Partidos 2026'!G:G,"E") -> 2 | J14: =COUNTIFS('Base_Partidos 2026'!C:C,A14,'Base_Partidos 2026'!G:G,"P") -> 4 | K14: =((H14*3+I14*1)/(H14+I14+J14)/3) -> 0.64444444 | L14: =COUNTIFS('Base_Partidos 2026'!C:C,A14,'Base_Partidos 2026'!H:H,"SI") -> 0
... A27: Otro | B27: =COUNTIF('Base_Partidos 2026'!C:C,A27) -> 4 | C27: =SUMIF('Base_Partidos 2026'!C:C,A27,'Base_Partidos 2026'!E:E) -> 1 | D27: =C27/B27 -> 0.25 | E27: =SUMIF('Base_Partidos 2026'!C:C,A27,'Base_Partidos 2026'!F:F) -> 0 | F27: =C27+E27 -> 1 | G27: =F27/B27 -> 0.25 | H27: =COUNTIFS('Base_Partidos 2026'!C:C,A27,'Base_Partidos 2026'!G:G,"G") -> 1 | I27: =COUNTIFS('Base_Partidos 2026'!C:C,A27,'Base_Partidos 2026'!G:G,"E") -> 0 | J27: =COUNTIFS('Base_Partidos 2026'!C:C,A27,'Base_Partidos 2026'!G:G,"P") -> 3 | K27: =((H27*3+I27*1)/(H27+I27+J27)/3) -> 0.25 | L27: =COUNTIFS('Base_Partidos 2026'!C:C,A27,'Base_Partidos 2026'!H:H,"SI") -> 0
A28: Luis Angel | B28: =COUNTIF('Base_Partidos 2026'!C:C,A28) -> 3 | C28: =SUMIF('Base_Partidos 2026'!C:C,A28,'Base_Partidos 2026'!E:E) -> 1 | D28: =C28/B28 -> 0.33333333 | E28: =SUMIF('Base_Partidos 2026'!C:C,A28,'Base_Partidos 2026'!F:F) -> 0 | F28: =C28+E28 -> 1 | G28: =F28/B28 -> 0.33333333 | H28: =COUNTIFS('Base_Partidos 2026'!C:C,A28,'Base_Partidos 2026'!G:G,"G") -> 1 | I28: =COUNTIFS('Base_Partidos 2026'!C:C,A28,'Base_Partidos 2026'!G:G,"E") -> 0 | J28: =COUNTIFS('Base_Partidos 2026'!C:C,A28,'Base_Partidos 2026'!G:G,"P") -> 2 | K28: =((H28*3+I28*1)/(H28+I28+J28)/3) -> 0.33333333 | L28: =COUNTIFS('Base_Partidos 2026'!C:C,A28,'Base_Partidos 2026'!H:H,"SI") -> 1 | M28: =N28/B28 -> 2 | N28: =SUMIF('Base_Partidos 2026'!C:C,A28,'Base_Partidos 2026'!I:I) -> 6
A29: Panela | B29: =COUNTIF('Base_Partidos 2026'!C:C,A29) -> 2 | C29: =SUMIF('Base_Partidos 2026'!C:C,A29,'Base_Partidos 2026'!E:E) -> 1 | D29: =C29/B29 -> 0.5 | E29: =SUMIF('Base_Partidos 2026'!C:C,A29,'Base_Partidos 2026'!F:F) -> 0 | F29: =C29+E29 -> 1 | G29: =F29/B29 -> 0.5 | H29: =COUNTIFS('Base_Partidos 2026'!C:C,A29,'Base_Partidos 2026'!G:G,"G") -> 0 | I29: =COUNTIFS('Base_Partidos 2026'!C:C,A29,'Base_Partidos 2026'!G:G,"E") -> 0 | J29: =COUNTIFS('Base_Partidos 2026'!C:C,A29,'Base_Partidos 2026'!G:G,"P") -> 2 | K29: =((H29*3+I29*1)/(H29+I29+J29)/3) -> 0 | L29: =COUNTIFS('Base_Partidos 2026'!C:C,A29,'Base_Partidos 2026'!H:H,"SI") -> 1
A30: Joan | B30: =COUNTIF('Base_Partidos 2026'!C:C,A30) -> 1 | C30: =SUMIF('Base_Partidos 2026'!C:C,A30,'Base_Partidos 2026'!E:E) -> 1 | D30: =C30/B30 -> 1 | E30: =SUMIF('Base_Partidos 2026'!C:C,A30,'Base_Partidos 2026'!F:F) -> 0 | F30: =C30+E30 -> 1 | G30: =F30/B30 -> 1 | H30: =COUNTIFS('Base_Partidos 2026'!C:C,A30,'Base_Partidos 2026'!G:G,"G") -> 0 | I30: =COUNTIFS('Base_Partidos 2026'!C:C,A30,'Base_Partidos 2026'!G:G,"E") -> 0 | J30: =COUNTIFS('Base_Partidos 2026'!C:C,A30,'Base_Partidos 2026'!G:G,"P") -> 1 | K30: =((H30*3+I30*1)/(H30+I30+J30)/3) -> 0 | L30: =COUNTIFS('Base_Partidos 2026'!C:C,A30,'Base_Partidos 2026'!H:H,"SI") -> 0
A31: Samuel F | B31: =COUNTIF('Base_Partidos 2026'!C:C,A31) -> 2 | C31: =SUMIF('Base_Partidos 2026'!C:C,A31,'Base_Partidos 2026'!E:E) -> 1 | D31: =C31/B31 -> 0.5 | E31: =SUMIF('Base_Partidos 2026'!C:C,A31,'Base_Partidos 2026'!F:F) -> 1 | F31: =C31+E31 -> 2 | G31: =F31/B31 -> 1 | H31: =COUNTIFS('Base_Partidos 2026'!C:C,A31,'Base_Partidos 2026'!G:G,"G") -> 1 | I31: =COUNTIFS('Base_Partidos 2026'!C:C,A31,'Base_Partidos 2026'!G:G,"E") -> 0 | J31: =COUNTIFS('Base_Partidos 2026'!C:C,A31,'Base_Partidos 2026'!G:G,"P") -> 1 | K31: =((H31*3+I31*1)/(H31+I31+J31)/3) -> 0.5 | L31: =COUNTIFS('Base_Partidos 2026'!C:C,A31,'Base_Partidos 2026'!H:H,"SI") -> 0
A32: Sebastian Wil | B32: =COUNTIF('Base_Partidos 2026'!C:C,A32) -> 1 | C32: =SUMIF('Base_Partidos 2026'!C:C,A32,'Base_Partidos 2026'!E:E) -> 1 | D32: =C32/B32 -> 1 | E32: =SUMIF('Base_Partidos 2026'!C:C,A32,'Base_Partidos 2026'!F:F) -> 0 | F32: =C32+E32 -> 1 | G32: =F32/B32 -> 1 | H32: =COUNTIFS('Base_Partidos 2026'!C:C,A32,'Base_Partidos 2026'!G:G,"G") -> 1 | I32: =COUNTIFS('Base_Partidos 2026'!C:C,A32,'Base_Partidos 2026'!G:G,"E") -> 0 | J32: =COUNTIFS('Base_Partidos 2026'!C:C,A32,'Base_Partidos 2026'!G:G,"P") -> 0 | K32: =((H32*3+I32*1)/(H32+I32+J32)/3) -> 1 | L32: =COUNTIFS('Base_Partidos 2026'!C:C,A32,'Base_Partidos 2026'!H:H,"SI") -> 0
A33: Diego Ortega | B33: =COUNTIF('Base_Partidos 2026'!C:C,A33) -> 22 | C33: =SUMIF('Base_Partidos 2026'!C:C,A33,'Base_Partidos 2026'!E:E) -> 0 | D33: =C33/B33 -> 0 | E33: =SUMIF('Base_Partidos 2026'!C:C,A33,'Base_Partidos 2026'!F:F) -> 2 | F33: =C33+E33 -> 2 | G33: =F33/B33 -> 0.090909091 | H33: =COUNTIFS('Base_Partidos 2026'!C:C,A33,'Base_Partidos 2026'!G:G,"G") -> 11 | I33: =COUNTIFS('Base_Partidos 2026'!C:C,A33,'Base_Partidos 2026'!G:G,"E") -> 2 | J33: =COUNTIFS('Base_Partidos 2026'!C:C,A33,'Base_Partidos 2026'!G:G,"P") -> 9 | K33: =((H33*3+I33*1)/(H33+I33+J33)/3) -> 0.53030303 | L33: =COUNTIFS('Base_Partidos 2026'!C:C,A33,'Base_Partidos 2026'!H:H,"SI") -> 3 | M33: =N33/B33 -> 3.0454545 | N33: =SUMIF('Base_Partidos 2026'!C:C,A33,'Base_Partidos 2026'!I:I) -> 67
A34: William Omaña | B34: =COUNTIF('Base_Partidos 2026'!C:C,A34) -> 18 | C34: =SUMIF('Base_Partidos 2026'!C:C,A34,'Base_Partidos 2026'!E:E) -> 0 | D34: =C34/B34 -> 0 | E34: =SUMIF('Base_Partidos 2026'!C:C,A34,'Base_Partidos 2026'!F:F) -> 1 | F34: =C34+E34 -> 1 | G34: =F34/B34 -> 0.055555556 | H34: =COUNTIFS('Base_Partidos 2026'!C:C,A34,'Base_Partidos 2026'!G:G,"G") -> 8 | I34: =COUNTIFS('Base_Partidos 2026'!C:C,A34,'Base_Partidos 2026'!G:G,"E") -> 2 | J34: =COUNTIFS('Base_Partidos 2026'!C:C,A34,'Base_Partidos 2026'!G:G,"P") -> 8 | K34: =((H34*3+I34*1)/(H34+I34+J34)/3) -> 0.48148148 | L34: =COUNTIFS('Base_Partidos 2026'!C:C,A34,'Base_Partidos 2026'!H:H,"SI") -> 3 | M34: =N34/B34 -> 3.1666667 | N34: =SUMIF('Base_Partidos 2026'!C:C,A34,'Base_Partidos 2026'!I:I) -> 57
A35: Luis TOTO | B35: =COUNTIF('Base_Partidos 2026'!C:C,A35) -> 21 | C35: =SUMIF('Base_Partidos 2026'!C:C,A35,'Base_Partidos 2026'!E:E) -> 0 | D35: =C35/B35 -> 0 | E35: =SUMIF('Base_Partidos 2026'!C:C,A35,'Base_Partidos 2026'!F:F) -> 1 | F35: =C35+E35 -> 1 | G35: =F35/B35 -> 0.047619048 | H35: =COUNTIFS('Base_Partidos 2026'!C:C,A35,'Base_Partidos 2026'!G:G,"G") -> 10 | I35: =COUNTIFS('Base_Partidos 2026'!C:C,A35,'Base_Partidos 2026'!G:G,"E") -> 4 | J35: =COUNTIFS('Base_Partidos 2026'!C:C,A35,'Base_Partidos 2026'!G:G,"P") -> 7 | K35: =((H35*3+I35*1)/(H35+I35+J35)/3) -> 0.53968254 | L35: =COUNTIFS('Base_Partidos 2026'!C:C,A35,'Base_Partidos 2026'!H:H,"SI") -> 0
A36: Edwin | B36: =COUNTIF('Base_Partidos 2026'!C:C,A36) -> 11 | C36: =SUMIF('Base_Partidos 2026'!C:C,A36,'Base_Partidos 2026'!E:E) -> 0 | D36: =C36/B36 -> 0 | E36: =SUMIF('Base_Partidos 2026'!C:C,A36,'Base_Partidos 2026'!F:F) -> 1 | F36: =C36+E36 -> 1 | G36: =F36/B36 -> 0.090909091 | H36: =COUNTIFS('Base_Partidos 2026'!C:C,A36,'Base_Partidos 2026'!G:G,"G") -> 3 | I36: =COUNTIFS('Base_Partidos 2026'!C:C,A36,'Base_Partidos 2026'!G:G,"E") -> 2 | J36: =COUNTIFS('Base_Partidos 2026'!C:C,A36,'Base_Partidos 2026'!G:G,"P") -> 6 | K36: =((H36*3+I36*1)/(H36+I36+J36)/3) -> 0.33333333 | L36: =COUNTIFS('Base_Partidos 2026'!C:C,A36,'Base_Partidos 2026'!H:H,"SI") -> 0
A37: Sergio Diaz | B37: =COUNTIF('Base_Partidos 2026'!C:C,A37) -> 15 | C37: =SUMIF('Base_Partidos 2026'!C:C,A37,'Base_Partidos 2026'!E:E) -> 0 | D37: =C37/B37 -> 0 | E37: =SUMIF('Base_Partidos 2026'!C:C,A37,'Base_Partidos 2026'!F:F) -> 1 | F37: =C37+E37 -> 1 | G37: =F37/B37 -> 0.066666667 | H37: =COUNTIFS('Base_Partidos 2026'!C:C,A37,'Base_Partidos 2026'!G:G,"G") -> 7 | I37: =COUNTIFS('Base_Partidos 2026'!C:C,A37,'Base_Partidos 2026'!G:G,"E") -> 2 | J37: =COUNTIFS('Base_Partidos 2026'!C:C,A37,'Base_Partidos 2026'!G:G,"P") -> 6 | K37: =((H37*3+I37*1)/(H37+I37+J37)/3) -> 0.51111111 | L37: =COUNTIFS('Base_Partidos 2026'!C:C,A37,'Base_Partidos 2026'!H:H,"SI") -> 2
A38: Rola | B38: =COUNTIF('Base_Partidos 2026'!C:C,A38) -> 6 | C38: =SUMIF('Base_Partidos 2026'!C:C,A38,'Base_Partidos 2026'!E:E) -> 0 | D38: =C38/B38 -> 0 | E38: =SUMIF('Base_Partidos 2026'!C:C,A38,'Base_Partidos 2026'!F:F) -> 0 | F38: =C38+E38 -> 0 | G38: =F38/B38 -> 0 | H38: =COUNTIFS('Base_Partidos 2026'!C:C,A38,'Base_Partidos 2026'!G:G,"G") -> 3 | I38: =COUNTIFS('Base_Partidos 2026'!C:C,A38,'Base_Partidos 2026'!G:G,"E") -> 0 | J38: =COUNTIFS('Base_Partidos 2026'!C:C,A38,'Base_Partidos 2026'!G:G,"P") -> 3 | K38: =((H38*3+I38*1)/(H38+I38+J38)/3) -> 0.5 | L38: =COUNTIFS('Base_Partidos 2026'!C:C,A38,'Base_Partidos 2026'!H:H,"SI") -> 0
A39: Eduard | B39: =COUNTIF('Base_Partidos 2026'!C:C,A39) -> 4 | C39: =SUMIF('Base_Partidos 2026'!C:C,A39,'Base_Partidos 2026'!E:E) -> 0 | D39: =C39/B39 -> 0 | E39: =SUMIF('Base_Partidos 2026'!C:C,A39,'Base_Partidos 2026'!F:F) -> 0 | F39: =C39+E39 -> 0 | G39: =F39/B39 -> 0 | H39: =COUNTIFS('Base_Partidos 2026'!C:C,A39,'Base_Partidos 2026'!G:G,"G") -> 2 | I39: =COUNTIFS('Base_Partidos 2026'!C:C,A39,'Base_Partidos 2026'!G:G,"E") -> 0 | J39: =COUNTIFS('Base_Partidos 2026'!C:C,A39,'Base_Partidos 2026'!G:G,"P") -> 2 | K39: =((H39*3+I39*1)/(H39+I39+J39)/3) -> 0.5 | L39: =COUNTIFS('Base_Partidos 2026'!C:C,A39,'Base_Partidos 2026'!H:H,"SI") -> 1
A40: Henry | B40: =COUNTIF('Base_Partidos 2026'!C:C,A40) -> 4 | C40: =SUMIF('Base_Partidos 2026'!C:C,A40,'Base_Partidos 2026'!E:E) -> 0 | D40: =C40/B40 -> 0 | E40: =SUMIF('Base_Partidos 2026'!C:C,A40,'Base_Partidos 2026'!F:F) -> 0 | F40: =C40+E40 -> 0 | G40: =F40/B40 -> 0 | H40: =COUNTIFS('Base_Partidos 2026'!C:C,A40,'Base_Partidos 2026'!G:G,"G") -> 1 | I40: =COUNTIFS('Base_Partidos 2026'!C:C,A40,'Base_Partidos 2026'!G:G,"E") -> 1 | J40: =COUNTIFS('Base_Partidos 2026'!C:C,A40,'Base_Partidos 2026'!G:G,"P") -> 2 | K40: =((H40*3+I40*1)/(H40+I40+J40)/3) -> 0.33333333 | L40: =COUNTIFS('Base_Partidos 2026'!C:C,A40,'Base_Partidos 2026'!H:H,"SI") -> 0 | M40: =N40/B40 -> 3.5 | N40: =SUMIF('Base_Partidos 2026'!C:C,A40,'Base_Partidos 2026'!I:I) -> 14
A41: Jex Costeño | B41: =COUNTIF('Base_Partidos 2026'!C:C,A41) -> 6 | C41: =SUMIF('Base_Partidos 2026'!C:C,A41,'Base_Partidos 2026'!E:E) -> 0 | D41: =C41/B41 -> 0 | E41: =SUMIF('Base_Partidos 2026'!C:C,A41,'Base_Partidos 2026'!F:F) -> 1 | F41: =C41+E41 -> 1 | G41: =F41/B41 -> 0.16666667 | H41: =COUNTIFS('Base_Partidos 2026'!C:C,A41,'Base_Partidos 2026'!G:G,"G") -> 2 | I41: =COUNTIFS('Base_Partidos 2026'!C:C,A41,'Base_Partidos 2026'!G:G,"E") -> 2 | J41: =COUNTIFS('Base_Partidos 2026'!C:C,A41,'Base_Partidos 2026'!G:G,"P") -> 2 | K41: =((H41*3+I41*1)/(H41+I41+J41)/3) -> 0.44444444 | L41: =COUNTIFS('Base_Partidos 2026'!C:C,A41,'Base_Partidos 2026'!H:H,"SI") -> 0
A42: Nany | B42: =COUNTIF('Base_Partidos 2026'!C:C,A42) -> 4 | C42: =SUMIF('Base_Partidos 2026'!C:C,A42,'Base_Partidos 2026'!E:E) -> 0 | D42: =C42/B42 -> 0 | E42: =SUMIF('Base_Partidos 2026'!C:C,A42,'Base_Partidos 2026'!F:F) -> 2 | F42: =C42+E42 -> 2 | G42: =F42/B42 -> 0.5 | H42: =COUNTIFS('Base_Partidos 2026'!C:C,A42,'Base_Partidos 2026'!G:G,"G") -> 2 | I42: =COUNTIFS('Base_Partidos 2026'!C:C,A42,'Base_Partidos 2026'!G:G,"E") -> 0 | J42: =COUNTIFS('Base_Partidos 2026'!C:C,A42,'Base_Partidos 2026'!G:G,"P") -> 2 | K42: =((H42*3+I42*1)/(H42+I42+J42)/3) -> 0.5 | L42: =COUNTIFS('Base_Partidos 2026'!C:C,A42,'Base_Partidos 2026'!H:H,"SI") -> 1
A43: Carime | B43: =COUNTIF('Base_Partidos 2026'!C:C,A43) -> 1 | C43: =SUMIF('Base_Partidos 2026'!C:C,A43,'Base_Partidos 2026'!E:E) -> 0 | D43: =C43/B43 -> 0 | E43: =SUMIF('Base_Partidos 2026'!C:C,A43,'Base_Partidos 2026'!F:F) -> 0 | F43: =C43+E43 -> 0 | G43: =F43/B43 -> 0 | H43: =COUNTIFS('Base_Partidos 2026'!C:C,A43,'Base_Partidos 2026'!G:G,"G") -> 0 | I43: =COUNTIFS('Base_Partidos 2026'!C:C,A43,'Base_Partidos 2026'!G:G,"E") -> 0 | J43: =COUNTIFS('Base_Partidos 2026'!C:C,A43,'Base_Partidos 2026'!G:G,"P") -> 1 | K43: =((H43*3+I43*1)/(H43+I43+J43)/3) -> 0 | L43: =COUNTIFS('Base_Partidos 2026'!C:C,A43,'Base_Partidos 2026'!H:H,"SI") -> 0
A44: Carime | B44: =COUNTIF('Base_Partidos 2026'!C:C,A44) -> 1 | C44: =SUMIF('Base_Partidos 2026'!C:C,A44,'Base_Partidos 2026'!E:E) -> 0 | D44: =C44/B44 -> 0 | E44: =SUMIF('Base_Partidos 2026'!C:C,A44,'Base_Partidos 2026'!F:F) -> 0 | F44: =C44+E44 -> 0 | G44: =F44/B44 -> 0 | H44: =COUNTIFS('Base_Partidos 2026'!C:C,A44,'Base_Partidos 2026'!G:G,"G") -> 0 | I44: =COUNTIFS('Base_Partidos 2026'!C:C,A44,'Base_Partidos 2026'!G:G,"E") -> 0 | J44: =COUNTIFS('Base_Partidos 2026'!C:C,A44,'Base_Partidos 2026'!G:G,"P") -> 1 | K44: =((H44*3+I44*1)/(H44+I44+J44)/3) -> 0 | L44: =COUNTIFS('Base_Partidos 2026'!C:C,A44,'Base_Partidos 2026'!H:H,"SI") -> 0
A45: Collantes Arquero | B45: =COUNTIF('Base_Partidos 2026'!C:C,A45) -> 2 | C45: =SUMIF('Base_Partidos 2026'!C:C,A45,'Base_Partidos 2026'!E:E) -> 0 | D45: =C45/B45 -> 0 | E45: =SUMIF('Base_Partidos 2026'!C:C,A45,'Base_Partidos 2026'!F:F) -> 0 | F45: =C45+E45 -> 0 | G45: =F45/B45 -> 0 | H45: =COUNTIFS('Base_Partidos 2026'!C:C,A45,'Base_Partidos 2026'!G:G,"G") -> 0 | I45: =COUNTIFS('Base_Partidos 2026'!C:C,A45,'Base_Partidos 2026'!G:G,"E") -> 1 | J45: =COUNTIFS('Base_Partidos 2026'!C:C,A45,'Base_Partidos 2026'!G:G,"P") -> 1 | K45: =((H45*3+I45*1)/(H45+I45+J45)/3) -> 0.16666667 | L45: =COUNTIFS('Base_Partidos 2026'!C:C,A45,'Base_Partidos 2026'!H:H,"SI") -> 0 | M45: =N45/B45 -> 5 | N45: =SUMIF('Base_Partidos 2026'!C:C,A45,'Base_Partidos 2026'!I:I) -> 10
A46: Grijalva Arquero | B46: =COUNTIF('Base_Partidos 2026'!C:C,A46) -> 1 | C46: =SUMIF('Base_Partidos 2026'!C:C,A46,'Base_Partidos 2026'!E:E) -> 0 | D46: =C46/B46 -> 0 | E46: =SUMIF('Base_Partidos 2026'!C:C,A46,'Base_Partidos 2026'!F:F) -> 0 | F46: =C46+E46 -> 0 | G46: =F46/B46 -> 0 | H46: =COUNTIFS('Base_Partidos 2026'!C:C,A46,'Base_Partidos 2026'!G:G,"G") -> 0 | I46: =COUNTIFS('Base_Partidos 2026'!C:C,A46,'Base_Partidos 2026'!G:G,"E") -> 0 | J46: =COUNTIFS('Base_Partidos 2026'!C:C,A46,'Base_Partidos 2026'!G:G,"P") -> 1 | K46: =((H46*3+I46*1)/(H46+I46+J46)/3) -> 0 | L46: =COUNTIFS('Base_Partidos 2026'!C:C,A46,'Base_Partidos 2026'!H:H,"SI") -> 0 | M46: =N46/B46 -> 5 | N46: =SUMIF('Base_Partidos 2026'!C:C,A46,'Base_Partidos 2026'!I:I) -> 5
A47: Sayago | B47: =COUNTIF('Base_Partidos 2026'!C:C,A47) -> 1 | C47: =SUMIF('Base_Partidos 2026'!C:C,A47,'Base_Partidos 2026'!E:E) -> 0 | D47: =C47/B47 -> 0 | E47: =SUMIF('Base_Partidos 2026'!C:C,A47,'Base_Partidos 2026'!F:F) -> 0 | F47: =C47+E47 -> 0 | G47: =F47/B47 -> 0 | H47: =COUNTIFS('Base_Partidos 2026'!C:C,A47,'Base_Partidos 2026'!G:G,"G") -> 0 | I47: =COUNTIFS('Base_Partidos 2026'!C:C,A47,'Base_Partidos 2026'!G:G,"E") -> 0 | J47: =COUNTIFS('Base_Partidos 2026'!C:C,A47,'Base_Partidos 2026'!G:G,"P") -> 1 | K47: =((H47*3+I47*1)/(H47+I47+J47)/3) -> 0 | L47: =COUNTIFS('Base_Partidos 2026'!C:C,A47,'Base_Partidos 2026'!H:H,"SI") -> 0
A48: Chucho | B48: =COUNTIF('Base_Partidos 2026'!C:C,A48) -> 0 | C48: =SUMIF('Base_Partidos 2026'!C:C,A48,'Base_Partidos 2026'!E:E) -> 0 | D48: =C48/B48 -> #DIV/0! | E48: =SUMIF('Base_Partidos 2026'!C:C,A48,'Base_Partidos 2026'!F:F) -> 0 | H48: =COUNTIFS('Base_Partidos 2026'!C:C,A48,'Base_Partidos 2026'!G:G,"G") -> 0 | I48: =COUNTIFS('Base_Partidos 2026'!C:C,A48,'Base_Partidos 2026'!G:G,"E") -> 0 | J48: =COUNTIFS('Base_Partidos 2026'!C:C,A48,'Base_Partidos 2026'!G:G,"P") -> 0 | K48: =((H48*3+I48*1)/(H48+I48+J48)/3) -> #DIV/0! | L48: =COUNTIFS('Base_Partidos 2026'!C:C,A48,'Base_Partidos 2026'!H:H,"SI") -> 0
A49: Jesus Arquero Luis A | B49: =COUNTIF('Base_Partidos 2026'!C:C,A49) -> 4 | C49: =SUMIF('Base_Partidos 2026'!C:C,A49,'Base_Partidos 2026'!E:E) -> 0 | D49: =C49/B49 -> 0 | E49: =SUMIF('Base_Partidos 2026'!C:C,A49,'Base_Partidos 2026'!F:F) -> 0 | F49: =C49+E49 -> 0 | G49: =F49/B49 -> 0 | H49: =COUNTIFS('Base_Partidos 2026'!C:C,A49,'Base_Partidos 2026'!G:G,"G") -> 2 | I49: =COUNTIFS('Base_Partidos 2026'!C:C,A49,'Base_Partidos 2026'!G:G,"E") -> 2 | J49: =COUNTIFS('Base_Partidos 2026'!C:C,A49,'Base_Partidos 2026'!G:G,"P") -> 0 | K49: =((H49*3+I49*1)/(H49+I49+J49)/3) -> 0.66666667 | L49: =COUNTIFS('Base_Partidos 2026'!C:C,A49,'Base_Partidos 2026'!H:H,"SI") -> 0 | M49: =N49/B49 -> 3 | N49: =SUMIF('Base_Partidos 2026'!C:C,A49,'Base_Partidos 2026'!I:I) -> 12
A50: Luis Angel Jugador | B50: =COUNTIF('Base_Partidos 2026'!C:C,A50) -> 3 | C50: =SUMIF('Base_Partidos 2026'!C:C,A50,'Base_Partidos 2026'!E:E) -> 0 | D50: =C50/B50 -> 0 | E50: =SUMIF('Base_Partidos 2026'!C:C,A50,'Base_Partidos 2026'!F:F) -> 0 | F50: =C50+E50 -> 0 | G50: =F50/B50 -> 0 | H50: =COUNTIFS('Base_Partidos 2026'!C:C,A50,'Base_Partidos 2026'!G:G,"G") -> 1 | I50: =COUNTIFS('Base_Partidos 2026'!C:C,A50,'Base_Partidos 2026'!G:G,"E") -> 1 | J50: =COUNTIFS('Base_Partidos 2026'!C:C,A50,'Base_Partidos 2026'!G:G,"P") -> 1 | K50: =((H50*3+I50*1)/(H50+I50+J50)/3) -> 0.44444444 | L50: =COUNTIFS('Base_Partidos 2026'!C:C,A50,'Base_Partidos 2026'!H:H,"SI") -> 0
A51: Puchis | B51: =COUNTIF('Base_Partidos 2026'!C:C,A51) -> 0 | C51: =SUMIF('Base_Partidos 2026'!C:C,A51,'Base_Partidos 2026'!E:E) -> 0 | D51: =C51/B51 -> #DIV/0! | E51: =SUMIF('Base_Partidos 2026'!C:C,A51,'Base_Partidos 2026'!F:F) -> 0 | H51: =COUNTIFS('Base_Partidos 2026'!C:C,A51,'Base_Partidos 2026'!G:G,"G") -> 0 | I51: =COUNTIFS('Base_Partidos 2026'!C:C,A51,'Base_Partidos 2026'!G:G,"E") -> 0 | J51: =COUNTIFS('Base_Partidos 2026'!C:C,A51,'Base_Partidos 2026'!G:G,"P") -> 0 | K51: =((H51*3+I51*1)/(H51+I51+J51)/3) -> #DIV/0! | L51: =COUNTIFS('Base_Partidos 2026'!C:C,A51,'Base_Partidos 2026'!H:H,"SI") -> 0
A52: Ricardo | B52: =COUNTIF('Base_Partidos 2026'!C:C,A52) -> 0 | C52: =SUMIF('Base_Partidos 2026'!C:C,A52,'Base_Partidos 2026'!E:E) -> 0 | D52: =C52/B52 -> #DIV/0! | E52: =SUMIF('Base_Partidos 2026'!C:C,A52,'Base_Partidos 2026'!F:F) -> 0 | H52: =COUNTIFS('Base_Partidos 2026'!C:C,A52,'Base_Partidos 2026'!G:G,"G") -> 0 | I52: =COUNTIFS('Base_Partidos 2026'!C:C,A52,'Base_Partidos 2026'!G:G,"E") -> 0 | J52: =COUNTIFS('Base_Partidos 2026'!C:C,A52,'Base_Partidos 2026'!G:G,"P") -> 0 | K52: =((H52*3+I52*1)/(H52+I52+J52)/3) -> #DIV/0! | L52: =COUNTIFS('Base_Partidos 2026'!C:C,A52,'Base_Partidos 2026'!H:H,"SI") -> 0

Sheet Poderes
A2: EQUIPO A BLANCO | B2: TOTAL 1 | C2: EQUIPO B NEGRO | D2: TOTAL 2
A3: =SUM(B4:B18) -> 55.8 | C3: =SUM(D4:D21) -> 56.7 | G3: EQUIPO BLANCO
A4: Diego Ortega Arquero | B4: =VLOOKUP(A4,Guerreros!$A$1:Guerreros!$B51,2,FALSE()) -> 6.4 | C4: Willian Omaña | D4: =VLOOKUP(C4,Guerreros!$A$1:Guerreros!$B51,2,FALSE()) -> 7.7 | G4: =A4 -> Diego Ortega Arquero
A5: Luis Miranda TOTO | B5: =VLOOKUP(A5,Guerreros!$A$1:Guerreros!$B58,2,FALSE()) -> 5.2 | C5: Sergio Díaz | D5: =VLOOKUP(C5,Guerreros!$A$1:Guerreros!$B72,2,FALSE()) -> 4.2 | F5: 2. Toto | G5: 14. Sergio S. | H5: 7. Navarro | I5: 12. Costeño
A6: Sergio Suárez | B6: =VLOOKUP(A6,Guerreros!$A$1:Guerreros!$B53,2,FALSE()) -> 7.4 | C6: Felipe Sasa | D6: =VLOOKUP(C6,Guerreros!$A$1:Guerreros!$B59,2,FALSE()) -> 7.2 | F6: 15. Robert | G6: 1. Arley | H6: 10. Japs
A7: Navarro | B7: =VLOOKUP(A7,Guerreros!$A$1:Guerreros!$B54,2,FALSE()) -> 5.5 | C7: Sergio Meneses | D7: =VLOOKUP(C7,Guerreros!$A$1:Guerreros!$B54,2,FALSE()) -> 5.1 | G7: 16. Maldonado
A8: Nany | B8: =VLOOKUP(A8,Guerreros!$A$1:Guerreros!$B57,2,FALSE()) -> 5.6 | C8: Luis Maldonado | D8: =VLOOKUP(C8,Guerreros!$A$1:Guerreros!$B57,2,FALSE()) -> 8.8
A9: Kevin Carrillo | B9: =VLOOKUP(A9,Guerreros!$A$1:Guerreros!$B58,2,FALSE()) -> 8.6 | C9: Camilo Arévalo | D9: =VLOOKUP(C9,Guerreros!$A$1:Guerreros!$B58,2,FALSE()) -> 7
A10: Javier Figueroa | B10: =VLOOKUP(A10,Guerreros!$A$1:Guerreros!$B59,2,FALSE()) -> 8 | C10: Silvia | D10: =VLOOKUP(C10,Guerreros!$A$1:Guerreros!$B59,2,FALSE()) -> 6 | G10: EQUIPO AZUL
A11: Japs | B11: =VLOOKUP(A11,Guerreros!$A$1:Guerreros!$B60,2,FALSE()) -> 5.3 | C11: Arley | D11: =VLOOKUP(C11,Guerreros!$A$1:Guerreros!$B60,2,FALSE()) -> 6.5 | G11: =C4 -> Willian Omaña
A12: Yamith | B12: =VLOOKUP(A12,Guerreros!$A$1:Guerreros!$B61,2,FALSE()) -> 3.8 | C12: Aleja | D12: =VLOOKUP(C12,Guerreros!$A$1:Guerreros!$B61,2,FALSE()) -> 4.2 | F12: 4. Jose | G12: 8. WiL | H12: 5. Sergio Díaz | I12: 11. Jaen
A13: JUGADORES | B13: =VLOOKUP(A13,Guerreros!$A$1:Guerreros!$B51,2,FALSE()) -> PUNTAJE | C13: JUGADORES | D13: =VLOOKUP(C13,Guerreros!$A$1:Guerreros!$B62,2,FALSE()) -> PUNTAJE | F13: 3. Aleja | G13: 6. Kevin Arce | H13: 13. Edwin
A14: JUGADORES | B14: =VLOOKUP(A14,Guerreros!$A$1:Guerreros!$B63,2,FALSE()) -> PUNTAJE | C14: JUGADORES | D14: =VLOOKUP(C14,Guerreros!$A$1:Guerreros!$B63,2,FALSE()) -> PUNTAJE | G14: 9. Boada
A15: JUGADORES | B15: =VLOOKUP(A15,Guerreros!$A$1:Guerreros!$B64,2,FALSE()) -> PUNTAJE | C15: JUGADORES | D15: =VLOOKUP(C15,Guerreros!$A$1:Guerreros!$B64,2,FALSE()) -> PUNTAJE
A16: JUGADORES | B16: =VLOOKUP(A16,Guerreros!$A$1:Guerreros!$B65,2,FALSE()) -> PUNTAJE | C16: JUGADORES | D16: =VLOOKUP(C16,Guerreros!$A$1:Guerreros!$B65,2,FALSE()) -> PUNTAJE
A17: JUGADORES | B17: =VLOOKUP(A17,Guerreros!$A$1:Guerreros!$B66,2,FALSE()) -> PUNTAJE | C17: JUGADORES | D17: =VLOOKUP(C17,Guerreros!$A$1:Guerreros!$B66,2,FALSE()) -> PUNTAJE
A18: JUGADORES | B18: =VLOOKUP(A18,Guerreros!$A$1:Guerreros!$B67,2,FALSE()) -> PUNTAJE | C18: JUGADORES | D18: =VLOOKUP(C18,Guerreros!$A$1:Guerreros!$B67,2,FALSE()) -> PUNTAJE
A19: JUGADORES | B19: =VLOOKUP(A19,Guerreros!$A$1:Guerreros!$B68,2,FALSE()) -> PUNTAJE | C19: JUGADORES | D19: =VLOOKUP(C19,Guerreros!$A$1:Guerreros!$B68,2,FALSE()) -> PUNTAJE
A20: JUGADORES | B20: =VLOOKUP(A20,Guerreros!$A$1:Guerreros!$B69,2,FALSE()) -> PUNTAJE | C20: JUGADORES | D20: =VLOOKUP(C20,Guerreros!$A$1:Guerreros!$B69,2,FALSE()) -> PUNTAJE
A21: JUGADORES | B21: =VLOOKUP(A21,Guerreros!$A$1:Guerreros!$B70,2,FALSE()) -> PUNTAJE | C21: JUGADORES | D21: =VLOOKUP(C21,Guerreros!$A$1:Guerreros!$B70,2,FALSE()) -> PUNTAJE
B23: 0 | D23: 0

Sheet limpio
A2: equipo A | B2: total | C2: equipo b | D2: total
A3: =SUM(B4:B23) -> #N/A | C3: =SUM(D4:D23) -> #N/A
A4: --- | B4: =VLOOKUP(A4,Guerreros!$A$1:Guerreros!$B51,2,FALSE()) -> #N/A | C4: --- | D4: =VLOOKUP(C4,Guerreros!$A$1:Guerreros!$B51,2,FALSE()) -> #N/A
A5: --- | B5: =VLOOKUP(A5,Guerreros!$A$1:Guerreros!$B52,2,FALSE()) -> #N/A | C5: --- | D5: =VLOOKUP(C5,Guerreros!$A$1:Guerreros!$B52,2,FALSE()) -> #N/A
A6: --- | B6: =VLOOKUP(A6,Guerreros!$A$1:Guerreros!$B53,2,FALSE()) -> #N/A | C6: --- | D6: =VLOOKUP(C6,Guerreros!$A$1:Guerreros!$B53,2,FALSE()) -> #N/A
A7: --- | B7: =VLOOKUP(A7,Guerreros!$A$1:Guerreros!$B54,2,FALSE()) -> #N/A | C7: --- | D7: =VLOOKUP(C7,Guerreros!$A$1:Guerreros!$B54,2,FALSE()) -> #N/A
A8: --- | B8: =VLOOKUP(A8,Guerreros!$A$1:Guerreros!$B57,2,FALSE()) -> #N/A | C8: --- | D8: =VLOOKUP(C8,Guerreros!$A$1:Guerreros!$B57,2,FALSE()) -> #N/A
A9: --- | B9: =VLOOKUP(A9,Guerreros!$A$1:Guerreros!$B58,2,FALSE()) -> #N/A | C9: --- | D9: =VLOOKUP(C9,Guerreros!$A$1:Guerreros!$B58,2,FALSE()) -> #N/A
A10: --- | B10: =VLOOKUP(A10,Guerreros!$A$1:Guerreros!$B59,2,FALSE()) -> #N/A | C10: --- | D10: =VLOOKUP(C10,Guerreros!$A$1:Guerreros!$B59,2,FALSE()) -> #N/A
A11: --- | B11: =VLOOKUP(A11,Guerreros!$A$1:Guerreros!$B60,2,FALSE()) -> #N/A | C11: --- | D11: =VLOOKUP(C11,Guerreros!$A$1:Guerreros!$B60,2,FALSE()) -> #N/A
A12: --- | B12: =VLOOKUP(A12,Guerreros!$A$1:Guerreros!$B61,2,FALSE()) -> #N/A | C12: --- | D12: =VLOOKUP(C12,Guerreros!$A$1:Guerreros!$B61,2,FALSE()) -> #N/A
A13: --- | B13: =VLOOKUP(A13,Guerreros!$A$1:Guerreros!$B62,2,FALSE()) -> #N/A | C13: --- | D13: =VLOOKUP(C13,Guerreros!$A$1:Guerreros!$B62,2,FALSE()) -> #N/A
A14: --- | B14: =VLOOKUP(A14,Guerreros!$A$1:Guerreros!$B63,2,FALSE()) -> #N/A | C14: --- | D14: =VLOOKUP(C14,Guerreros!$A$1:Guerreros!$B63,2,FALSE()) -> #N/A
A15: --- | B15: =VLOOKUP(A15,Guerreros!$A$1:Guerreros!$B64,2,FALSE()) -> #N/A | C15: --- | D15: =VLOOKUP(C15,Guerreros!$A$1:Guerreros!$B64,2,FALSE()) -> #N/A
A16: --- | B16: =VLOOKUP(A16,Guerreros!$A$1:Guerreros!$B65,2,FALSE()) -> #N/A | C16: --- | D16: =VLOOKUP(C16,Guerreros!$A$1:Guerreros!$B65,2,FALSE()) -> #N/A
A17: --- | B17: =VLOOKUP(A17,Guerreros!$A$1:Guerreros!$B66,2,FALSE()) -> #N/A | C17: --- | D17: =VLOOKUP(C17,Guerreros!$A$1:Guerreros!$B66,2,FALSE()) -> #N/A
A18: --- | B18: =VLOOKUP(A18,Guerreros!$A$1:Guerreros!$B67,2,FALSE()) -> #N/A | C18: --- | D18: =VLOOKUP(C18,Guerreros!$A$1:Guerreros!$B67,2,FALSE()) -> #N/A
A19: --- | B19: =VLOOKUP(A19,Guerreros!$A$1:Guerreros!$B68,2,FALSE()) -> #N/A | C19: --- | D19: =VLOOKUP(C19,Guerreros!$A$1:Guerreros!$B68,2,FALSE()) -> #N/A
... A21: --- | B21: =VLOOKUP(A21,Guerreros!$A$1:Guerreros!$B70,2,FALSE()) -> #N/A | C21: --- | D21: =VLOOKUP(C21,Guerreros!$A$1:Guerreros!$B70,2,FALSE()) -> #N/A

Sheet Guerreros
A1: JUGADORES | B1: PUNTAJE
A2: Luis Maldonado | B2: 8.8
A3: Kevin Carrillo | B3: 8.6
A4: Abreo | B4: 8.3
A5: Jairo Boada | B5: 8.1
A6: Andres Gemelo | B6: 8.1
A7: Puchis | B7: 8
A8: Javier Figueroa | B8: 8
A9: Willian Omaña | B9: 7.7
A10: Oscar | B10: 7.5
A11: Luis Ángel Arquero | B11: 7.5
A12: Sergio Suárez | B12: 7.4
A13: Felipe Sasa | B13: 7.2
... A47: Daniel Panela | B47: 2.2

Sheet Base_Partidos 2026
A1: Fecha | B1: Partido # | C1: Jugador | D1: Equipo | E1: Goles | F1: Asistencias | G1: Resultado | H1: MVP | I1: Goles Arquero | J1: Malla Acumulado
A2: 46024 | B2: 1 | C2: Luis Angel | D2: Negro | E2: 0 | F2: 0 | G2: G | I2: 4
A3: 46024 | B3: 1 | C3: Luis Toto | D3: Negro | E3: 0 | F3: 0 | G3: G
A4: 46024 | B4: 1 | C4: Jose | D4: Negro | E4: 0 | F4: 0 | G4: G
A5: 46024 | B5: 1 | C5: Jesica Navarro | D5: Negro | E5: 0 | F5: 0 | G5: G
A6: 46024 | B6: 1 | C6: Arley | D6: Negro | E6: 2 | F6: 1 | G6: G | H6: SI
A7: 46024 | B7: 1 | C7: Jaen | D7: Negro | E7: 0 | F7: 1 | G7: G
A8: 46024 | B8: 1 | C8: Kevin Arce | D8: Negro | E8: 1 | F8: 0 | G8: G
A9: 46024 | B9: 1 | C9: Otro | D9: Otros | E9: 1 | F9: 0 | G9: G
A10: 46024 | B10: 1 | C10: Felipe Sasa | D10: Negro | E10: 0 | F10: 1 | G10: G
A11: 46024 | B11: 1 | C11: Yamith | D11: Negro | E11: 1 | F11: 0 | G11: G
A12: 46024 | B12: 1 | C12: Diego Ortega | D12: Blanco | E12: 0 | F12: 0 | G12: P | I12: 5
A13: 46024 | B13: 1 | C13: Edwin | D13: Blanco | E13: 0 | F13: 0 | G13: P
A14: 46024 | B14: 1 | C14: Sergio Suarez | D14: Blanco | E14: 1 | F14: 0 | G14: P
A15: 46024 | B15: 1 | C15: Sergio Diaz | D15: Blanco | E15: 0 | F15: 0 | G15: P
A16: 46024 | B16: 1 | C16: Silvia | D16: Blanco | E16: 1 | F16: 0 | G16: P | H16: SI
A17: 46024 | B17: 1 | C17: Freddy Manrique | D17: Blanco | E17: 0 | F17: 0 | G17: P
A18: 46024 | B18: 1 | C18: Boada | D18: Blanco | E18: 1 | F18: 0 | G18: P
A19: 46024 | B19: 1 | C19: Samuel F | D19: Blanco | E19: 1 | F19: 0 | G19: P
A20: 46024 | B20: 1 | C20: Otro | D20: Blanco | E20: 0 | F20: 0 | G20: P
A21: 46024 | B21: 1 | C21: Sayago | D21: Blanco | E21: 0 | F21: 0 | G21: P
A22: 46028 | B22: 2 | C22: Diego Ortega | D22: Blanco | E22: 0 | F22: 0 | G22: G | I22: 1
A23: 46028 | B23: 2 | C23: Sergio Diaz | D23: Blanco | E23: 0 | F23: 0 | G23: G
A24: 46028 | B24: 2 | C24: WIL | D24: Blanco | E24: 0 | F24: 0 | G24: G
A25: 46028 | B25: 2 | C25: Eduard | D25: Blanco | E25: 0 | F25: 0 | G25: G | H25: SI
A26: 46028 | B26: 2 | C26: Jesica Navarro | D26: Blanco | E26: 1 | F26: 0 | G26: G
A27: 46028 | B27: 2 | C27: Abreo | D27: Blanco | E27: 1 | F27: 0 | G27: G
A28: 46028 | B28: 2 | C28: Kevin Arce | D28: Blanco | E28: 0 | F28: 0 | G28: G
A29: 46028 | B29: 2 | C29: Arley | D29: Blanco | E29: 0 | F29: 0 | G29: G
A30: 46028 | B30: 2 | C30: Yamith | D30: Blanco | E30: 0 | F30: 0 | G30: G
A31: 46028 | B31: 2 | C31: Japs | D31: Blanco | E31: 0 | F31: 2 | G31: G
A32: 46028 | B32: 2 | C32: Henry | D32: Negro | E32: 0 | F32: 0 | G32: P
A33: 46028 | B33: 2 | C33: Edwin | D33: Negro | E33: 0 | F33: 0 | G33: P
A34: 46028 | B34: 2 | C34: Sergio Suarez | D34: Negro | E34: 0 | F34: 0 | G34: P
A35: 46028 | B35: 2 | C35: Jose | D35: Negro | E35: 0 | F35: 0 | G35: P
A36: 46028 | B36: 2 | C36: Luis TOTO | D36: Negro | E36: 0 | F36: 0 | G36: P
A37: 46028 | B37: 2 | C37: Silvia | D37: Negro | E37: 0 | F37: 1 | G37: P
A38: 46028 | B38: 2 | C38: Kevin Carrillo | D38: Negro | E38: 0 | F38: 0 | G38: P
A39: 46028 | B39: 2 | C39: Luis Angel | D39: Negro | E39: 0 | F39: 0 | G39: P | I39: 2
A40: 46028 | B40: 2 | C40: Otro | D40: Negro | E40: 0 | F40: 0 | G40: P
...
